Workbook

Sheet DASHBOARD
B2: MIYAA SAAB — GOLD JEWELLERY
B3: Consolidated P&L Dashboard · Partners: MS & SG · Investor Presentation
B4: Source: P&L Report 1 (SG Design – Sold Items) + P&L Report 2 (MS Design – Stock Holding Cost)
B6: EXECUTIVE SUMMARY — KEY PERFORMANCE INDICATORS
B7: TOTAL PIECES | D7: SOLD PIECES | F7: IN STOCK | H7: TOTAL GOLD WEIGHT (g) [Fine] | J7: P&L 1 HOLDING PROFIT (₹) | N7: Check
B8: =COUNTA('sale resgister'!B2:B100) -> 44 | D8: =COUNTIF('sale resgister'!M2:M100,"Sold") -> 18 | F8: =COUNTIF('sale resgister'!M2:M100,"Stock") -> 26 | H8: =SUM('sale resgister'!H2:H100) -> 1020.3537 | J8: ='P&L REPORT 1'!J18 -> 325589.48 | N8: =ROUND(+J8+B10+D10,0)=ROUND(F10+H10+J10,0) -> TRUE
B9: P&L 2 HOLDING PROFIT (₹) | D9: P&L 3 HOLDING PROFIT (₹) | F9: MS TOTAL SHARE (₹) | H9: SG TOTAL SHARE (₹) | J9: TOTAL OP. COST 15% (₹)
B10: =SUM('Pivot Report 2'!C2:C48)+SUM('Pivot Report 2'!D2:D48)+SUM('Pivot Report 2'!B2:B48) -> 86631.75 | D10: ='P&L REPORT 3'!P15+'P&L REPORT 3'!Q15+'P&L REPORT 3'!R15 -> 170042.6 | F10: ='P&L REPORT 1'!L18+SUM('Pivot Report 2'!C2:C48)+'P&L REPORT 3'!Q15 -> 296954.54 | H10: ='P&L REPORT 1'!M18+SUM('Pivot Report 2'!D2:D48)+'P&L REPORT 3'!R15 -> 197969.75 | J10: ='P&L REPORT 1'!K18+SUM('Pivot Report 2'!B2:B48)+'P&L REPORT 3'!P15 -> 87339.55
B12: P&L REPORT 1 — SG DESIGN (SOLD ITEMS) · 22K GOLD MANUFACTURING
B13: TAG NO | C13: SALE DATE | D13: WT (g) | E13: GOLD RATE 22K (₹) | F13: LABOUR COST (₹) | G13: LABOUR SELL PRICE (₹) | H13: SHARABLE PROFIT (₹) | I13: OP COST 15% (₹) | J13: MS SHARE (₹) | K13: SG SHARE (₹)
B14: ='P&L REPORT 1'!A2 -> MBAN32 | C14: ='P&L REPORT 1'!B2 -> 45757 | D14: ='P&L REPORT 1'!C2 -> 46.893 | E14: ='P&L REPORT 1'!D2 -> 9428 | F14: ='P&L REPORT 1'!F2 -> 0 | G14: ='P&L REPORT 1'!H2 -> 442107.2 | H14: ='P&L REPORT 1'!J2 -> 30947.504 | I14: ='P&L REPORT 1'!K2 -> 4642.13 | J14: ='P&L REPORT 1'!L2 -> 15783.22 | K14: ='P&L REPORT 1'!N2 -> 0
B15: ='P&L REPORT 1'!A3 -> MBAN37 | C15: ='P&L REPORT 1'!B3 -> 45922 | D15: ='P&L REPORT 1'!C3 -> 26.34 | E15: ='P&L REPORT 1'!D3 -> 10191 | F15: ='P&L REPORT 1'!F3 -> 0 | G15: ='P&L REPORT 1'!H3 -> 268430.94 | H15: ='P&L REPORT 1'!J3 -> 29527.403 | I15: ='P&L REPORT 1'!K3 -> 4429.11 | J15: ='P&L REPORT 1'!L3 -> 15058.98 | K15: ='P&L REPORT 1'!N3 -> 0
B16: ='P&L REPORT 1'!A4 -> MBAN38 | C16: ='P&L REPORT 1'!B4 -> 45878 | D16: ='P&L REPORT 1'!C4 -> 29.302 | E16: ='P&L REPORT 1'!D4 -> 9333 | F16: ='P&L REPORT 1'!F4 -> 0 | G16: ='P&L REPORT 1'!H4 -> 273475.57 | H16: ='P&L REPORT 1'!J4 -> 21878.045 | I16: ='P&L REPORT 1'!K4 -> 3281.71 | J16: ='P&L REPORT 1'!L4 -> 11157.8 | K16: ='P&L REPORT 1'!N4 -> 0
B17: ='P&L REPORT 1'!A5 -> MBRAC7 | C17: ='P&L REPORT 1'!B5 -> 46093 | D17: ='P&L REPORT 1'!C5 -> 3.589 | E17: ='P&L REPORT 1'!D5 -> 14764 | F17: ='P&L REPORT 1'!F5 -> 0 | G17: ='P&L REPORT 1'!H5 -> 52987.996 | H17: ='P&L REPORT 1'!J5 -> 6888.4395 | I17: ='P&L REPORT 1'!K5 -> 1033.27 | J17: ='P&L REPORT 1'!L5 -> 3513.1 | K17: ='P&L REPORT 1'!N5 -> 0
B18: ='P&L REPORT 1'!A6 -> MBAN41 | C18: ='P&L REPORT 1'!B6 -> 45901 | D18: ='P&L REPORT 1'!C6 -> 47.076 | E18: ='P&L REPORT 1'!D6 -> 9637 | F18: ='P&L REPORT 1'!F6 -> 0 | G18: ='P&L REPORT 1'!H6 -> 453671.41 | H18: ='P&L REPORT 1'!J6 -> 49903.855 | I18: ='P&L REPORT 1'!K6 -> 7485.58 | J18: ='P&L REPORT 1'!L6 -> 25450.97 | K18: ='P&L REPORT 1'!N6 -> 0
B19: ='P&L REPORT 1'!A7 -> MRING2 | C19: ='P&L REPORT 1'!B7 -> 45884 | D19: ='P&L REPORT 1'!C7 -> 5.462 | E19: ='P&L REPORT 1'!D7 -> 9200 | F19: ='P&L REPORT 1'!F7 -> 0 | G19: ='P&L REPORT 1'!H7 -> 50250.4 | H19: ='P&L REPORT 1'!J7 -> 6281.3 | I19: ='P&L REPORT 1'!K7 -> 942.2 | J19: ='P&L REPORT 1'!L7 -> 3203.46 | K19: ='P&L REPORT 1'!N7 -> 0
B20: ='P&L REPORT 1'!A8 -> MRING3 | C20: ='P&L REPORT 1'!B8 -> 45986 | D20: ='P&L REPORT 1'!C8 -> 3.501 | E20: ='P&L REPORT 1'!D8 -> 11316 | F20: ='P&L REPORT 1'!F8 -> 0 | G20: ='P&L REPORT 1'!H8 -> 39617.316 | H20: ='P&L REPORT 1'!J8 -> 5546.4242 | I20: ='P&L REPORT 1'!K8 -> 831.96 | J20: ='P&L REPORT 1'!L8 -> 2828.68 | K20: ='P&L REPORT 1'!N8 -> 0
B21: ='P&L REPORT 1'!A9 -> MBRAC12 | C21: ='P&L REPORT 1'!B9 -> 46017 | D21: ='P&L REPORT 1'!C9 -> 25.231 | E21: ='P&L REPORT 1'!D9 -> 12737 | F21: ='P&L REPORT 1'!F9 -> 0 | G21: ='P&L REPORT 1'!H9 -> 321367.25 | H21: ='P&L REPORT 1'!J9 -> 48205.087 | I21: ='P&L REPORT 1'!K9 -> 7230.76 | J21: ='P&L REPORT 1'!L9 -> 24584.6 | K21: ='P&L REPORT 1'!N9 -> 0
B22: ='P&L REPORT 1'!A10 -> MBRAC14 | C22: ='P&L REPORT 1'!B10 -> 46053 | D22: ='P&L REPORT 1'!C10 -> 33.418 | E22: ='P&L REPORT 1'!D10 -> 13487 | F22: ='P&L REPORT 1'!F10 -> 0 | G22: ='P&L REPORT 1'!H10 -> 450708.57 | H22: ='P&L REPORT 1'!J10 -> 58592.114 | I22: ='P&L REPORT 1'!K10 -> 8788.82 | J22: ='P&L REPORT 1'!L10 -> 29881.98 | K22: ='P&L REPORT 1'!N10 -> 0
B23: ='P&L REPORT 1'!A11 -> MBRAC11 | C23: ='P&L REPORT 1'!B11 -> 46049 | D23: ='P&L REPORT 1'!C11 -> 30.627 | E23: ='P&L REPORT 1'!D11 -> 15100 | F23: ='P&L REPORT 1'!F11 -> 0 | G23: ='P&L REPORT 1'!H11 -> 462467.7 | H23: ='P&L REPORT 1'!J11 -> 43934.431 | I23: ='P&L REPORT 1'!K11 -> 6590.16 | J23: ='P&L REPORT 1'!L11 -> 22406.56 | K23: ='P&L REPORT 1'!N11 -> 0
B24: ='P&L REPORT 1'!A12 -> MPENDAL5 | C24: ='P&L REPORT 1'!B12 -> 45968 | D24: ='P&L REPORT 1'!C12 -> 1.052 | E24: ='P&L REPORT 1'!D12 -> 10601 | F24: ='P&L REPORT 1'!F12 -> 0 | G24: ='P&L REPORT 1'!H12 -> 11152.252 | H24: ='P&L REPORT 1'!J12 -> 1449.7928 | I24: ='P&L REPORT 1'!K12 -> 217.47 | J24: ='P&L REPORT 1'!L12 -> 739.39 | K24: ='P&L REPORT 1'!N12 -> 0
B25: ='P&L REPORT 1'!A13 -> MPENDAL7 | C25: ='P&L REPORT 1'!B13 -> 46039 | D25: ='P&L REPORT 1'!C13 -> 2.093 | E25: ='P&L REPORT 1'!D13 -> 13075 | F25: ='P&L REPORT 1'!F13 -> 0 | G25: ='P&L REPORT 1'!H13 -> 27365.975 | H25: ='P&L REPORT 1'!J13 -> 3010.2572 | I25: ='P&L REPORT 1'!K13 -> 451.54 | J25: ='P&L REPORT 1'!L13 -> 1535.23 | K25: ='P&L REPORT 1'!N13 -> 0
... B29: ='P&L REPORT 1'!A17 -> MRING8 | C29: ='P&L REPORT 1'!B17 -> 46003 | D29: ='P&L REPORT 1'!C17 -> 4.431 | E29: ='P&L REPORT 1'!D17 -> 12308 | F29: ='P&L REPORT 1'!F17 -> 0 | G29: ='P&L REPORT 1'!H17 -> 54536.748 | H29: ='P&L REPORT 1'!J17 -> 7089.7772 | I29: ='P&L REPORT 1'!K17 -> 1063.47 | J29: ='P&L REPORT 1'!L17 -> 3615.78 | K29: ='P&L REPORT 1'!N17 -> 0
B30: GRAND TOTAL | D30: =SUM(D14:D29) -> 266.001 | E30: =SUM(E14:E29) -> 186544 | F30: =SUM(F14:F29) -> 0 | G30: =SUM(G14:G29) -> 2989683.3 | H30: =SUM(H14:H29) -> 325589.48 | I30: =SUM(I14:I29) -> 48838.45 | J30: =SUM(J14:J29) -> 166050.62 | K30: ='P&L REPORT 1'!N18 -> 0
B32: P&L REPORT 2 — MS DESIGN (STOCK HOLDING COST ACCRUAL) · ITEM-WISE SUMMARY
B33: TAG NO | C33: STATUS | D33: SOLD DATE | E33: KT | F33: TOTAL OP COST (₹) | G33: MS SHARE (₹) | H33: SG SHARE (₹) | I33: MS PROFIT IN GOLD (g) | J33: BATCH | K33: NOTES
B34: BALI100437 | C34: =IF(D34>"","Sold","Stock") -> Stock | D34: =(VLOOKUP(B34,'sale resgister'!B:J,8,0)) -> 0 | E34: =VLOOKUP(B34,'sale resgister'!B:D,3,0) -> 18 | F34: =VLOOKUP(B34,'Pivot Report 2'!A:D,2,0) -> 0 | G34: =VLOOKUP(B34,'Pivot Report 2'!A:D,3,0) -> 0 | H34: =VLOOKUP(B34,'Pivot Report 2'!A:D,4,0) -> 0 | I34: =SUMIF('P&L REPORT 2'!B:B,B34,'P&L REPORT 2'!S:S) -> 0 | J34: =VLOOKUP(B34,'sale resgister'!B:C,2,0) -> Batch 3 | K34: Holding cost accruing
B35: BAN1842 | C35: =IF(D35>"","Sold","Stock") -> Stock | D35: =(VLOOKUP(B35,'sale resgister'!B:J,8,0)) -> 0 | E35: =VLOOKUP(B35,'sale resgister'!B:D,3,0) -> 22 | F35: =VLOOKUP(B35,'Pivot Report 2'!A:D,2,0) -> 0 | G35: =VLOOKUP(B35,'Pivot Report 2'!A:D,3,0) -> 0 | H35: =VLOOKUP(B35,'Pivot Report 2'!A:D,4,0) -> 0 | I35: =SUMIF('P&L REPORT 2'!B:B,B35,'P&L REPORT 2'!S:S) -> 0 | J35: =VLOOKUP(B35,'sale resgister'!B:C,2,0) -> Batch 1 | K35: Holding cost accruing
B36: BAN1843 | C36: =IF(D36>"","Sold","Stock") -> Stock | D36: =(VLOOKUP(B36,'sale resgister'!B:J,8,0)) -> 0 | E36: =VLOOKUP(B36,'sale resgister'!B:D,3,0) -> 22 | F36: =VLOOKUP(B36,'Pivot Report 2'!A:D,2,0) -> 0 | G36: =VLOOKUP(B36,'Pivot Report 2'!A:D,3,0) -> 0 | H36: =VLOOKUP(B36,'Pivot Report 2'!A:D,4,0) -> 0 | I36: =SUMIF('P&L REPORT 2'!B:B,B36,'P&L REPORT 2'!S:S) -> 0 | J36: =VLOOKUP(B36,'sale resgister'!B:C,2,0) -> Batch 1 | K36: Holding cost accruing
B37: BAN1845 | C37: =IF(D37>"","Sold","Stock") -> Stock | D37: =(VLOOKUP(B37,'sale resgister'!B:J,8,0)) -> 0 | E37: =VLOOKUP(B37,'sale resgister'!B:D,3,0) -> 22 | F37: =VLOOKUP(B37,'Pivot Report 2'!A:D,2,0) -> 0 | G37: =VLOOKUP(B37,'Pivot Report 2'!A:D,3,0) -> 0 | H37: =VLOOKUP(B37,'Pivot Report 2'!A:D,4,0) -> 0 | I37: =SUMIF('P&L REPORT 2'!B:B,B37,'P&L REPORT 2'!S:S) -> 0 | J37: =VLOOKUP(B37,'sale resgister'!B:C,2,0) -> Batch 1 | K37: Holding cost accruing
B38: BAN1846 | C38: =IF(D38>"","Sold","Stock") -> Stock | D38: =(VLOOKUP(B38,'sale resgister'!B:J,8,0)) -> 0 | E38: =VLOOKUP(B38,'sale resgister'!B:D,3,0) -> 22 | F38: =VLOOKUP(B38,'Pivot Report 2'!A:D,2,0) -> 0 | G38: =VLOOKUP(B38,'Pivot Report 2'!A:D,3,0) -> 0 | H38: =VLOOKUP(B38,'Pivot Report 2'!A:D,4,0) -> 0 | I38: =SUMIF('P&L REPORT 2'!B:B,B38,'P&L REPORT 2'!S:S) -> 0 | J38: =VLOOKUP(B38,'sale resgister'!B:C,2,0) -> Batch 1 | K38: Holding cost accruing
B39: BAN1847 | C39: =IF(D39>"","Sold","Stock") -> Stock | D39: =(VLOOKUP(B39,'sale resgister'!B:J,8,0)) -> 0 | E39: =VLOOKUP(B39,'sale resgister'!B:D,3,0) -> 22 | F39: =VLOOKUP(B39,'Pivot Report 2'!A:D,2,0) -> 3848.81 | G39: =VLOOKUP(B39,'Pivot Report 2'!A:D,3,0) -> 13085.96 | H39: =VLOOKUP(B39,'Pivot Report 2'!A:D,4,0) -> 8723.99 | I39: =SUMIF('P&L REPORT 2'!B:S,B39,'P&L REPORT 2'!S:S) -> 0.953 | J39: =VLOOKUP(B39,'sale resgister'!B:C,2,0) -> Batch 1 | K39: Profit settled
B40: BAN1867(MBAN4/MBAN8) | C40: =IF(D40>"","Sold","Stock") -> Stock | D40: =(VLOOKUP(B40,'sale resgister'!B:J,8,0)) -> 0 | E40: =VLOOKUP(B40,'sale resgister'!B:D,3,0) -> 22 | F40: =VLOOKUP(B40,'Pivot Report 2'!A:D,2,0) -> 0 | G40: =VLOOKUP(B40,'Pivot Report 2'!A:D,3,0) -> 0 | H40: =VLOOKUP(B40,'Pivot Report 2'!A:D,4,0) -> 0 | I40: =SUMIF('P&L REPORT 2'!B:S,B40,'P&L REPORT 2'!S:S) -> 0 | J40: =VLOOKUP(B40,'sale resgister'!B:C,2,0) -> Batch 1 | K40: Holding cost accruing
B41: BAN1868(MBAN6/MBAN7/MBAN12) | C41: =IF(D41>"","Sold","Stock") -> Stock | D41: =(VLOOKUP(B41,'sale resgister'!B:J,8,0)) -> 0 | E41: =VLOOKUP(B41,'sale resgister'!B:D,3,0) -> 22 | F41: =VLOOKUP(B41,'Pivot Report 2'!A:D,2,0) -> 1424.14 | G41: =VLOOKUP(B41,'Pivot Report 2'!A:D,3,0) -> 4842.1 | H41: =VLOOKUP(B41,'Pivot Report 2'!A:D,4,0) -> 3228.08 | I41: =SUMIF('P&L REPORT 2'!B:S,B41,'P&L REPORT 2'!S:S) -> 0.312 | J41: =VLOOKUP(B41,'sale resgister'!B:C,2,0) -> Batch 1 | K41: Profit settled
B42: BAN1925 | C42: =IF(D42>"","Sold","Stock") -> Stock | D42: =(VLOOKUP(B42,'sale resgister'!B:J,8,0)) -> 0 | E42: =VLOOKUP(B42,'sale resgister'!B:D,3,0) -> 22 | F42: =VLOOKUP(B42,'Pivot Report 2'!A:D,2,0) -> 846.37 | G42: =VLOOKUP(B42,'Pivot Report 2'!A:D,3,0) -> 2877.68 | H42: =VLOOKUP(B42,'Pivot Report 2'!A:D,4,0) -> 1918.45 | I42: =SUMIF('P&L REPORT 2'!B:S,B42,'P&L REPORT 2'!S:S) -> 0.184 | J42: =VLOOKUP(B42,'sale resgister'!B:C,2,0) -> Batch 2 | K42: Profit settled
B43: BAN1938 | C43: =IF(D43>"","Sold","Stock") -> Stock | D43: =(VLOOKUP(B43,'sale resgister'!B:J,8,0)) -> 0 | E43: =VLOOKUP(B43,'sale resgister'!B:D,3,0) -> 22 | F43: =VLOOKUP(B43,'Pivot Report 2'!A:D,2,0) -> 846.37 | G43: =VLOOKUP(B43,'Pivot Report 2'!A:D,3,0) -> 2877.68 | H43: =VLOOKUP(B43,'Pivot Report 2'!A:D,4,0) -> 1918.45 | I43: =SUMIF('P&L REPORT 2'!B:S,B43,'P&L REPORT 2'!S:S) -> 0.184 | J43: =VLOOKUP(B43,'sale resgister'!B:C,2,0) -> Batch 2 | K43: Profit settled
B44: BAN1939 | C44: =IF(D44>"","Sold","Stock") -> Stock | D44: =(VLOOKUP(B44,'sale resgister'!B:J,8,0)) -> 0 | E44: =VLOOKUP(B44,'sale resgister'!B:D,3,0) -> 22 | F44: =VLOOKUP(B44,'Pivot Report 2'!A:D,2,0) -> 846.37 | G44: =VLOOKUP(B44,'Pivot Report 2'!A:D,3,0) -> 2877.68 | H44: =VLOOKUP(B44,'Pivot Report 2'!A:D,4,0) -> 1918.45 | I44: =SUMIF('P&L REPORT 2'!B:S,B44,'P&L REPORT 2'!S:S) -> 0.184 | J44: =VLOOKUP(B44,'sale resgister'!B:C,2,0) -> Batch 2 | K44: Profit settled
B45: BAN2015 | C45: =IF(D45>"","Sold","Stock") -> Stock | D45: =(VLOOKUP(B45,'sale resgister'!B:J,8,0)) -> 0 | E45: =VLOOKUP(B45,'sale resgister'!B:D,3,0) -> 22 | F45: =VLOOKUP(B45,'Pivot Report 2'!A:D,2,0) -> 0 | G45: =VLOOKUP(B45,'Pivot Report 2'!A:D,3,0) -> 0 | H45: =VLOOKUP(B45,'Pivot Report 2'!A:D,4,0) -> 0 | I45: =SUMIF('P&L REPORT 2'!B:B,B45,'P&L REPORT 2'!S:S) -> 0 | J45: =VLOOKUP(B45,'sale resgister'!B:C,2,0) -> Batch 3 | K45: Holding cost accruing
B46: BAN2016 | C46: =IF(D46>"","Sold","Stock") -> Stock | D46: =(VLOOKUP(B46,'sale resgister'!B:J,8,0)) -> 0 | E46: =VLOOKUP(B46,'sale resgister'!B:D,3,0) -> 22 | F46: =VLOOKUP(B46,'Pivot Report 2'!A:D,2,0) -> 0 | G46: =VLOOKUP(B46,'Pivot Report 2'!A:D,3,0) -> 0 | H46: =VLOOKUP(B46,'Pivot Report 2'!A:D,4,0) -> 0 | I46: =SUMIF('P&L REPORT 2'!B:B,B46,'P&L REPORT 2'!S:S) -> 0 | J46: =VLOOKUP(B46,'sale resgister'!B:C,2,0) -> Batch 3 | K46: Holding cost accruing
B47: BAN2017 | C47: =IF(D47>"","Sold","Stock") -> Stock | D47: =(VLOOKUP(B47,'sale resgister'!B:J,8,0)) -> 0 | E47: =VLOOKUP(B47,'sale resgister'!B:D,3,0) -> 22 | F47: =VLOOKUP(B47,'Pivot Report 2'!A:D,2,0) -> 0 | G47: =VLOOKUP(B47,'Pivot Report 2'!A:D,3,0) -> 0 | H47: =VLOOKUP(B47,'Pivot Report 2'!A:D,4,0) -> 0 | I47: =SUMIF('P&L REPORT 2'!B:B,B47,'P&L REPORT 2'!S:S) -> 0 | J47: =VLOOKUP(B47,'sale resgister'!B:C,2,0) -> Batch 3 | K47: Holding cost accruing
...

Sheet Pivot Report 2
B1: Summary of P&L Report 2
B3: Values
A4: Row Labels | B4: Sum of Operating Cost | C4: Sum of MS Share | D4: Sum of SG Share
A5: BALI100437 | B5: 0 | C5: 0 | D5: 0
A6: BAN1842 | B6: 0 | C6: 0 | D6: 0
A7: BAN1843 | B7: 0 | C7: 0 | D7: 0
A8: BAN1845 | B8: 0 | C8: 0 | D8: 0
A9: BAN1846 | B9: 0 | C9: 0 | D9: 0
A10: BAN1847 | B10: 3848.81 | C10: 13085.96 | D10: 8723.99
A11: BAN1867(MBAN4/MBAN8) | B11: 0 | C11: 0 | D11: 0
A12: BAN1868(MBAN6/MBAN7/MBAN12) | B12: 1424.14 | C12: 4842.1 | D12: 3228.08
A13: BAN1925 | B13: 846.37 | C13: 2877.68 | D13: 1918.45
A14: BAN1938 | B14: 846.37 | C14: 2877.68 | D14: 1918.45
A15: BAN1939 | B15: 846.37 | C15: 2877.68 | D15: 1918.45
A16: BAN2015 | B16: 0 | C16: 0 | D16: 0
... A49: TAG NO | B49: 0 | C49: 0 | D49: 0
A50: (blank)
A51: Grand Total | B51: 12994.71 | C51: 44182.19 | D51: 29454.85
B55: Report 1 | C55: =+'P&L REPORT 1'!L18 -> 166050.62
B56: Report 2 | C56: =+C51 -> 44182.19
B57: Report 3 | C57: =+'P&L REPORT 3'!Q15 -> 86721.73
B58: Total | C58: =SUM(C55:C57) -> 296954.54

Sheet sale resgister
A1: Date | B1: Tag no. | C1: Batch | D1: Kt | E1: Gross Wt | F1: N.WT | G1: Wastage | H1: Fine | I1: Stock out | J1: Date of Sales | K1: Customer Name | L1: Labour | M1: Status
A2: 10.4.2025 | B2: BAN1842 | C2: Batch 1 | D2: 22 | E2: 43.467 | F2: 43.467 | G2: 92 | H2: =F2*G2% -> 39.98964 | M2: Stock | O2: =+TEXT(H2,"0.000") -> 39.990
A3: 10.4.2025 | B3: BAN1847 | C3: Batch 1 | D3: 22 | E3: 46.893 | F3: 46.893 | G3: 92 | H3: =F3*G3% -> 43.14156 | J3: 45757 | K3: TASNEEM AUNTY | L3: 30724 | M3: Sold | O3: =+TEXT(H3,"0.000") -> 43.142
A4: 10.4.2025 | B4: BAN1846 | C4: Batch 1 | D4: 22 | E4: 36.795 | F4: 32.44 | G4: 92 | H4: =F4*G4% -> 29.8448 | M4: Stock | O4: =+TEXT(H4,"0.000") -> 29.845
A5: 10.4.2025 | B5: BAN1845 | C5: Batch 1 | D5: 22 | E5: 28.552 | F5: 28.552 | G5: 92 | H5: =F5*G5% -> 26.26784 | M5: Stock | O5: =+TEXT(H5,"0.000") -> 26.268
A6: 10.4.2025 | B6: BAN1867(MBAN4/MBAN8) | C6: Batch 1 | D6: 22 | E6: 27.5 | F6: 27.5 | G6: 92 | H6: =F6*G6% -> 25.3 | M6: Stock | O6: =+TEXT(H6,"0.000") -> 25.300
A7: 10.4.2025 | B7: BAN1868(MBAN6/MBAN7/MBAN12) | C7: Batch 1 | D7: 22 | E7: 26.34 | F7: 26.34 | G7: 92 | H7: =F7*G7% -> 24.2328 | J7: 45922 | K7: IBRAHIM FAKHRI | L7: 21514 | M7: Sold | O7: =+TEXT(H7,"0.000") -> 24.233
A8: 10.4.2025 | B8: BAN1843 | C8: Batch 1 | D8: 22 | E8: 26.967 | F8: 26.967 | G8: 92 | H8: =F8*G8% -> 24.80964 | M8: Stock | O8: =+TEXT(H8,"0.000") -> 24.810
A9: 10.4.2025 | B9: MBAN1 | C9: Batch 1 | D9: 22 | E9: 29.302 | F9: 29.302 | G9: 92 | H9: =F9*G9% -> 26.95784 | J9: 45878 | K9: SAKINA JHABUA | L9: 21878 | M9: Sold | O9: =+TEXT(H9,"0.000") -> 26.958
A10: 10.4.2025 | B10: BRAC99440(MBRAC1) | C10: Batch 1 | D10: 22 | E10: 3.589 | F10: 3.589 | G10: 92 | H10: =F10*G10% -> 3.30188 | J10: 46093 | K10: ARWA RAMPURAWALA | L10: 11884 | M10: Sold | O10: =+TEXT(H10,"0.000") -> 3.302
A11: 10.4.2025 | B11: COIN 50GM 4 PCS | C11: Batch 1 | D11: 24 | E11: 200 | F11: 200 | G11: 99.5 | H11: =F11*G11% -> 199 | M11: Stock | O11: =+TEXT(H11,"0.000") -> 199.000
A12: 10.4.2025 | B12: MIX BANGLES 97.110 @ 90% | C12: Batch 1 | E12: 97.11 | F12: 97.11 | G12: 90 | H12: =F12*G12% -> 87.399 | M12: Stock | O12: =+TEXT(H12,"0.000") -> 87.399
A13: 30.7.2025 | B13: BAN1925 | C13: Batch 2 | D13: 22 | E13: 15.692 | F13: 15.692 | G13: 92 | H13: =F13*G13% -> 14.43664 | J13: 45901 | K13: BATUL PITHEWAN | L13: 16635 | M13: Sold | O13: =+TEXT(H13,"0.000") -> 14.437
A14: 30.7.2025 | B14: BAN1938 | C14: Batch 2 | D14: 22 | E14: 15.692 | F14: 15.692 | G14: 92 | H14: =F14*G14% -> 14.43664 | J14: 45901 | K14: KHUZEMA PITHEWAN | L14: 16635 | M14: Sold | O14: =+TEXT(H14,"0.000") -> 14.437
A15: 30.7.2025 | B15: BAN1939 | C15: Batch 2 | D15: 22 | E15: 15.692 | F15: 15.692 | G15: 92 | H15: =F15*G15% -> 14.43664 | J15: 45901 | K15: UMMEHANI PITHEWAN | L15: 16635 | M15: Sold | O15: =+TEXT(H15,"0.000") -> 14.437
A16: 30.7.2025 | B16: RIN103096 | C16: Batch 3 | D16: 22 | E16: 5.462 | F16: 5.462 | G16: 92 | H16: =F16*G16% -> 5.02504 | J16: 45884 | K16: FARIDA RAJ | L16: 6281 | M16: Sold | O16: =+TEXT(H16,"0.000") -> 5.025
A17: 30.7.2025 | B17: RIN103097 | C17: Batch 3 | D17: 22 | E17: 3.501 | F17: 3.501 | G17: 92 | H17: =F17*G17% -> 3.22092 | J17: 45986 | K17: ABDUL QADIR | L17: 5546 | M17: Sold | O17: =+TEXT(H17,"0.000") -> 3.221
A18: 24.10.2025 | B18: BAN2025 | C18: Batch 3 | D18: 22 | E18: 27.293 | F18: 27.293 | G18: 92 | H18: =F18*G18% -> 25.10956 | M18: Stock | O18: =+TEXT(H18,"0.000") -> 25.110
A19: 24.10.2025 | B19: BAN2022 | C19: Batch 3 | D19: 22 | E19: 42.445 | F19: 42.445 | G19: 92 | H19: =F19*G19% -> 39.0494 | M19: Stock | O19: =+TEXT(H19,"0.000") -> 39.049
A20: 24.10.2025 | B20: BAN2023 | C20: Batch 3 | D20: 22 | E20: 17.214 | F20: 17.214 | G20: 92 | H20: =F20*G20% -> 15.83688 | M20: Stock | O20: =+TEXT(H20,"0.000") -> 15.837
A21: 24.10.2025 | B21: BRAC99559 | C21: Batch 3 | D21: 22 | E21: 25.231 | F21: 25.231 | G21: 92 | H21: =F21*G21% -> 23.21252 | J21: 46017 | K21: BURHANUDDIN UJJAINWALA | L21: 48205 | M21: Sold | O21: =+TEXT(H21,"0.000") -> 23.213
A22: 24.10.2025 | B22: BRAC99564 | C22: Batch 3 | D22: 22 | E22: 30.881 | F22: 30.881 | G22: 92 | H22: =F22*G22% -> 28.41052 | M22: Stock | O22: =+TEXT(H22,"0.000") -> 28.411
A23: 24.10.2025 | B23: BRAC99565 | C23: Batch 3 | D23: 22 | E23: 12.442 | F23: 12.442 | G23: 92 | H23: =F23*G23% -> 11.44664 | M23: Stock | O23: =+TEXT(H23,"0.000") -> 11.447
A24: 24.10.2025 | B24: BAN2017 | C24: Batch 3 | D24: 22 | E24: 51.675 | F24: 51.675 | G24: 92 | H24: =F24*G24% -> 47.541 | M24: Stock | O24: =+TEXT(H24,"0.000") -> 47.541
A25: 24.10.2025 | B25: BAN2016 | C25: Batch 3 | D25: 22 | E25: 35.528 | F25: 32.528 | G25: 92 | H25: =F25*G25% -> 29.92576 | M25: Stock | O25: =+TEXT(H25,"0.000") -> 29.926
A26: 24.10.2025 | B26: BAN2015 | C26: Batch 3 | D26: 22 | E26: 32.886 | F26: 32.886 | G26: 92 | H26: =F26*G26% -> 30.25512 | M26: Stock | O26: =+TEXT(H26,"0.000") -> 30.255
A27: 24.10.2025 | B27: BRAC99558 | C27: Batch 3 | D27: 22 | E27: 22.321 | F27: 22.321 | G27: 92 | H27: =F27*G27% -> 20.53532 | M27: Stock | O27: =+TEXT(H27,"0.000") -> 20.535
A28: 24.10.2025 | B28: BRAC99563 | C28: Batch 3 | D28: 22 | E28: 11.032 | F28: 10.882 | G28: 88 | H28: =F28*G28% -> 9.57616 | M28: Stock | O28: =+TEXT(H28,"0.000") -> 9.576
A29: 24.10.2025 | B29: BRAC99560 | C29: Batch 3 | D29: 22 | E29: 18.646 | F29: 18.646 | G29: 92 | H29: =F29*G29% -> 17.15432 | M29: Stock | O29: =+TEXT(H29,"0.000") -> 17.154
A30: 24.10.2025 | B30: BAN2024 | C30: Batch 3 | D30: 22 | E30: 22.624 | F30: 22.624 | G30: 92 | H30: =F30*G30% -> 20.81408 | M30: Stock | O30: =+TEXT(H30,"0.000") -> 20.814
A31: 24.10.2025 | B31: BAN2019 | C31: Batch 3 | D31: 22 | E31: 15.721 | F31: 15.721 | G31: 92 | H31: =F31*G31% -> 14.46332 | M31: Stock | O31: =+TEXT(H31,"0.000") -> 14.463
A32: 24.10.2025 | B32: BRAC99561 | C32: Batch 3 | D32: 22 | E32: 33.418 | F32: 33.418 | G32: 92 | H32: =F32*G32% -> 30.74456 | J32: 46042 | K32: KULSUM BABUKHAN | L32: 58588 | M32: Sold | O32: =+TEXT(H32,"0.000") -> 30.745
A33: 24.10.2025 | B33: BAN2018 | C33: Batch 3 | D33: 22 | E33: 25.158 | F33: 25.158 | G33: 92 | H33: =F33*G33% -> 23.14536 | M33: Stock | O33: =+TEXT(H33,"0.000") -> 23.145
A34: 24.10.2025 | B34: BRAC99562 | C34: Batch 3 | D34: 22 | E34: 30.627 | F34: 30.627 | G34: 92 | H34: =F34*G34% -> 28.17684 | J34: 46049 | K34: FATEMA TIKIWALA | L34: 43934 | M34: Sold | O34: =+TEXT(H34,"0.000") -> 28.177
A35: 24.10.2025 | B35: BALI100437 | C35: Batch 3 | D35: 18 | E35: 3.376 | F35: 3.376 | G35: 76 | H35: =F35*G35% -> 2.56576 | M35: Stock | O35: =+TEXT(H35,"0.000") -> 2.566
A36: 24.10.2025 | B36: PDL92919 | C36: Batch 3 | D36: 22 | E36: 2.267 | F36: 2.267 | G36: 92 | H36: =F36*G36% -> 2.08564 | M36: Stock | O36: =+TEXT(H36,"0.000") -> 2.086
A37: 24.10.2025 | B37: PDL92918 | C37: Batch 3 | D37: 21 | E37: 1.052 | F37: 1.052 | G37: 88 | H37: =F37*G37% -> 0.92576 | J37: 45968 | K37: UMMEHANI SALIM | L37: 1450 | M37: Sold | O37: =+TEXT(H37,"0.000") -> 0.926
A38: 24.10.2025 | B38: PDL92917 | C38: Batch 3 | D38: 21 | E38: 0.993 | F38: 0.993 | G38: 88 | H38: =F38*G38% -> 0.87384 | M38: Stock | O38: =+TEXT(H38,"0.000") -> 0.874
A39: 24.10.2025 | B39: PDL92916 | C39: Batch 3 | D39: 22 | E39: 2.093 | F39: 2.093 | G39: 92 | H39: =F39*G39% -> 1.92556 | J39: 46039 | K39: MARIYA KANCHWALA | L39: 3010 | M39: Sold | O39: =+TEXT(H39,"0.000") -> 1.926
A40: 24.10.2025 | B40: PDL92915 | C40: Batch 3 | D40: 22 | E40: 2.289 | F40: 2.289 | G40: 92 | H40: =F40*G40% -> 2.10588 | M40: Stock | O40: =+TEXT(H40,"0.000") -> 2.106
...

Sheet P&L REPORT 1
A1: TAG NO | B1: Actual Sales Date | C1: New SG Design Introduced | D1: Gold Rate 22K | E1: Purity | F1: Labour cost Price | G1: Labour Cost Charged | H1: GOLD SELL Price | I1: Labour Profit Charged | J1: Labour Sharable Profit | K1: Operating Cost 15% | L1: MS Share | M1: SG Share
A2: MBAN32 | B2: 45757 | C2: 46.893 | D2: 9428 | E2: 22 | G2: 0 | H2: =C2*D2 -> 442107.2 | I2: =H2*7% -> 30947.504 | J2: =+I2-G2 -> 30947.504 | K2: =ROUND(+J2*15%,2) -> 4642.13 | L2: =ROUND(+(J2-K2)*60%,2) -> 15783.22 | M2: =ROUND(+(J2-K2)*40%,2) -> 10522.15
A3: MBAN37 | B3: 45922 | C3: 26.34 | D3: 10191 | E3: 22 | H3: =C3*D3 -> 268430.94 | I3: =H3*11% -> 29527.403 | J3: =+I3-G3 -> 29527.403 | K3: =ROUND(+J3*15%,2) -> 4429.11 | L3: =ROUND(+(J3-K3)*60%,2) -> 15058.98 | M3: =ROUND(+(J3-K3)*40%,2) -> 10039.32
A4: MBAN38 | B4: 45878 | C4: 29.302 | D4: 9333 | E4: 22 | H4: =C4*D4 -> 273475.57 | I4: =H4*8% -> 21878.045 | J4: =+I4-G4 -> 21878.045 | K4: =ROUND(+J4*15%,2) -> 3281.71 | L4: =ROUND(+(J4-K4)*60%,2) -> 11157.8 | M4: =ROUND(+(J4-K4)*40%,2) -> 7438.53
A5: MBRAC7 | B5: 46093 | C5: 3.589 | D5: 14764 | E5: 22 | H5: =C5*D5 -> 52987.996 | I5: =H5*13% -> 6888.4395 | J5: =+I5-G5 -> 6888.4395 | K5: =ROUND(+J5*15%,2) -> 1033.27 | L5: =ROUND(+(J5-K5)*60%,2) -> 3513.1 | M5: =ROUND(+(J5-K5)*40%,2) -> 2342.07
A6: MBAN41 | B6: 45901 | C6: 47.076 | D6: 9637 | E6: 22 | H6: =C6*D6 -> 453671.41 | I6: =H6*11% -> 49903.855 | J6: =+I6-G6 -> 49903.855 | K6: =ROUND(+J6*15%,2) -> 7485.58 | L6: =ROUND(+(J6-K6)*60%,2) -> 25450.97 | M6: =ROUND(+(J6-K6)*40%,2) -> 16967.31
A7: MRING2 | B7: 45884 | C7: 5.462 | D7: 9200 | E7: 22 | H7: =C7*D7 -> 50250.4 | I7: =H7*12.5% -> 6281.3 | J7: =+I7-G7 -> 6281.3 | K7: =ROUND(+J7*15%,2) -> 942.2 | L7: =ROUND(+(J7-K7)*60%,2) -> 3203.46 | M7: =ROUND(+(J7-K7)*40%,2) -> 2135.64
A8: MRING3 | B8: 45986 | C8: 3.501 | D8: 11316 | E8: 22 | H8: =C8*D8 -> 39617.316 | I8: =H8*14% -> 5546.4242 | J8: =+I8-G8 -> 5546.4242 | K8: =ROUND(+J8*15%,2) -> 831.96 | L8: =ROUND(+(J8-K8)*60%,2) -> 2828.68 | M8: =ROUND(+(J8-K8)*40%,2) -> 1885.79
A9: MBRAC12 | B9: 46017 | C9: 25.231 | D9: 12737 | E9: 22 | H9: =C9*D9 -> 321367.25 | I9: =H9*15% -> 48205.087 | J9: =+I9-G9 -> 48205.087 | K9: =ROUND(+J9*15%,2) -> 7230.76 | L9: =ROUND(+(J9-K9)*60%,2) -> 24584.6 | M9: =ROUND(+(J9-K9)*40%,2) -> 16389.73
A10: MBRAC14 | B10: 46053 | C10: 33.418 | D10: 13487 | E10: 22 | H10: =C10*D10 -> 450708.57 | I10: =H10*13% -> 58592.114 | J10: =+I10-G10 -> 58592.114 | K10: =ROUND(+J10*15%,2) -> 8788.82 | L10: =ROUND(+(J10-K10)*60%,2) -> 29881.98 | M10: =ROUND(+(J10-K10)*40%,2) -> 19921.32
A11: MBRAC11 | B11: 46049 | C11: 30.627 | D11: 15100 | E11: 22 | H11: =C11*D11 -> 462467.7 | I11: =H11*9.5% -> 43934.431 | J11: =+I11-G11 -> 43934.431 | K11: =ROUND(+J11*15%,2) -> 6590.16 | L11: =ROUND(+(J11-K11)*60%,2) -> 22406.56 | M11: =ROUND(+(J11-K11)*40%,2) -> 14937.71
A12: MPENDAL5 | B12: 45968 | C12: 1.052 | D12: 10601 | E12: 21 | H12: =C12*D12 -> 11152.252 | I12: =H12*13% -> 1449.7928 | J12: =+I12-G12 -> 1449.7928 | K12: =ROUND(+J12*15%,2) -> 217.47 | L12: =ROUND(+(J12-K12)*60%,2) -> 739.39 | M12: =ROUND(+(J12-K12)*40%,2) -> 492.93
A13: MPENDAL7 | B13: 46039 | C13: 2.093 | D13: 13075 | E13: 22 | H13: =C13*D13 -> 27365.975 | I13: =H13*11% -> 3010.2572 | J13: =+I13-G13 -> 3010.2572 | K13: =ROUND(+J13*15%,2) -> 451.54 | L13: =ROUND(+(J13-K13)*60%,2) -> 1535.23 | M13: =ROUND(+(J13-K13)*40%,2) -> 1023.49
A14: MRING4 | B14: 45985 | C14: 2.179 | D14: 11343 | E14: 22 | H14: =C14*D14 -> 24716.397 | I14: =H14*12% -> 2965.9676 | J14: =+I14-G14 -> 2965.9676 | K14: =ROUND(+J14*15%,2) -> 444.9 | L14: =ROUND(+(J14-K14)*60%,2) -> 1512.64 | M14: =ROUND(+(J14-K14)*40%,2) -> 1008.43
A15: MRING5 | B15: 46050 | C15: 1.577 | D15: 12565 | E15: 18 | H15: =C15*D15 -> 19815.005 | I15: =H15*23% -> 4557.4512 | J15: =+I15-G15 -> 4557.4512 | K15: =ROUND(+J15*15%,2) -> 683.62 | L15: =ROUND(+(J15-K15)*60%,2) -> 2324.3 | M15: =ROUND(+(J15-K15)*40%,2) -> 1549.53
A16: MRING7 | B16: 45972 | C16: 3.23 | D16: 11459 | E16: 22 | H16: =C16*D16 -> 37012.57 | I16: =H16*13% -> 4811.6341 | J16: =+I16-G16 -> 4811.6341 | K16: =ROUND(+J16*15%,2) -> 721.75 | L16: =ROUND(+(J16-K16)*60%,2) -> 2453.93 | M16: =ROUND(+(J16-K16)*40%,2) -> 1635.95
A17: MRING8 | B17: 46003 | C17: 4.431 | D17: 12308 | E17: 22 | H17: =C17*D17 -> 54536.748 | I17: =H17*13% -> 7089.7772 | J17: =+I17-G17 -> 7089.7772 | K17: =ROUND(+J17*15%,2) -> 1063.47 | L17: =ROUND(+(J17-K17)*60%,2) -> 3615.78 | M17: =ROUND(+(J17-K17)*40%,2) -> 2410.52
A18: TOTAL | H18: =SUM(H2:H17) -> 2989683.3 | I18: =SUM(I2:I17) -> 325589.48 | J18: =SUM(J2:J17) -> 325589.48 | K18: =SUM(K2:K17) -> 48838.45 | L18: =SUM(L2:L17) -> 166050.62 | M18: =SUM(M2:M17) -> 110700.42

Sheet P&L REPORT 2
G1: 46112 | H1: 0.07
A2: Sr. No | B2: TAG NO | C2: Actual Sales Date | D2: Purity | E2: MS design Sold | F2: New Stk Introduce on | G2: New SG Design Introduced | H2: Sales PM | I2: Gold Rate 24K | J2: Purity | K2: Labour cost Price | L2: Labour Cost Charged | M2: Labour Sell Price | N2: Labour Profit Charged | O2: Labour Sharable Profit | P2: Operating Cost 15% | Q2: MS Share | R2: SG Share | S2: MS Profit in Gold | W2: DO NOT Delete
A3: 1 | B3: =INDEX('sale resgister'!B:B,A3+1,1) -> BAN1842 | C3: =+VLOOKUP(B3,'sale resgister'!B:J,9,0) -> 0 | D3: =+VLOOKUP(B3,'sale resgister'!B:J,2,0) -> Batch 1 | E3: =IF(C3=0,0,VLOOKUP(B3,'sale resgister'!B:J,4,0)) -> 0 | F3: =DATE(YEAR(C3),MONTH(C3)+1,1) -> 32 | G3: =E3 -> 0 | H3: =ROUND(+G3*$H$1,3) -> 0 | I3: =IFERROR(+VLOOKUP(F3,$W$3:$X$15,2,0),0) -> 0 | J3: 22 | K3: =ROUND(+H3*97%,3) -> 0 | L3: =(K3-H3*92%)*I3 -> 0 | M3: =ROUND(I3*92%*H3,2) -> 0 | N3: =ROUND(+M3*0.11,2) -> 0 | O3: =+N3-L3 -> 0 | P3: =ROUND(+O3*15%,2) -> 0 | Q3: =ROUND(+(O3-P3)*60%,2) -> 0 | R3: =ROUND(+(O3-P3)*40%,2) -> 0 | S3: =IFERROR(ROUND(+Q3/(I3/92%),3),0) -> 0 | W3: 45748 | X3: 9370
B4: =+B3 -> BAN1842 | F4: =IF(+DATE(YEAR(F3),MONTH(F3)+1,1)>$G$1+1,0,+DATE(YEAR(F3),MONTH(F3)+1,1)) -> 61 | G4: =ROUND(IF(F4=0,0,(G3+S3)),3) -> 0 | H4: =ROUND(+G4*$H$1,3) -> 0 | I4: =IFERROR(+VLOOKUP(F4,$W$3:$X$15,2,0),0) -> 0 | J4: 22 | K4: =ROUND(+H4*97%,3) -> 0 | L4: =(K4-H4*92%)*I4 -> 0 | M4: =ROUND(I4*92%*H4,2) -> 0 | N4: =ROUND(+M4*0.11,2) -> 0 | O4: =+N4-L4 -> 0 | P4: =ROUND(+O4*15%,2) -> 0 | Q4: =ROUND(+(O4-P4)*60%,2) -> 0 | R4: =ROUND(+(O4-P4)*40%,2) -> 0 | S4: =IFERROR(ROUND(+Q4/(I4/92%),3),0) -> 0 | W4: 45778 | X4: 9953
B5: =+B4 -> BAN1842 | F5: =IF(+DATE(YEAR(F4),MONTH(F4)+1,1)>$G$1+1,0,+DATE(YEAR(F4),MONTH(F4)+1,1)) -> 92 | G5: =ROUND(IF(F5=0,0,(G4+S4)),3) -> 0 | H5: =ROUND(+G5*$H$1,3) -> 0 | I5: =IFERROR(+VLOOKUP(F5,$W$3:$X$15,2,0),0) -> 0 | J5: 22 | K5: =ROUND(+H5*97%,3) -> 0 | L5: =(K5-H5*92%)*I5 -> 0 | M5: =ROUND(I5*92%*H5,2) -> 0 | N5: =ROUND(+M5*0.11,2) -> 0 | O5: =+N5-L5 -> 0 | P5: =ROUND(+O5*15%,2) -> 0 | Q5: =ROUND(+(O5-P5)*60%,2) -> 0 | R5: =ROUND(+(O5-P5)*40%,2) -> 0 | S5: =IFERROR(ROUND(+Q5/(I5/92%),3),0) -> 0 | W5: 45809 | X5: 9966
B6: =+B5 -> BAN1842 | F6: =IF(+DATE(YEAR(F5),MONTH(F5)+1,1)>$G$1+1,0,+DATE(YEAR(F5),MONTH(F5)+1,1)) -> 122 | G6: =ROUND(IF(F6=0,0,(G5+S5)),3) -> 0 | H6: =ROUND(+G6*$H$1,3) -> 0 | I6: =IFERROR(+VLOOKUP(F6,$W$3:$X$15,2,0),0) -> 0 | J6: 22 | K6: =ROUND(+H6*97%,3) -> 0 | L6: =(K6-H6*92%)*I6 -> 0 | M6: =ROUND(I6*92%*H6,2) -> 0 | N6: =ROUND(+M6*0.11,2) -> 0 | O6: =+N6-L6 -> 0 | P6: =ROUND(+O6*15%,2) -> 0 | Q6: =ROUND(+(O6-P6)*60%,2) -> 0 | R6: =ROUND(+(O6-P6)*40%,2) -> 0 | S6: =IFERROR(ROUND(+Q6/(I6/92%),3),0) -> 0 | W6: 45839 | X6: 10008
B7: =+B6 -> BAN1842 | F7: =IF(+DATE(YEAR(F6),MONTH(F6)+1,1)>$G$1+1,0,+DATE(YEAR(F6),MONTH(F6)+1,1)) -> 153 | G7: =ROUND(IF(F7=0,0,(G6+S6)),3) -> 0 | H7: =ROUND(+G7*$H$1,3) -> 0 | I7: =IFERROR(+VLOOKUP(F7,$W$3:$X$15,2,0),0) -> 0 | J7: 22 | K7: =ROUND(+H7*97%,3) -> 0 | L7: =(K7-H7*92%)*I7 -> 0 | M7: =ROUND(I7*92%*H7,2) -> 0 | N7: =ROUND(+M7*0.11,2) -> 0 | O7: =+N7-L7 -> 0 | P7: =ROUND(+O7*15%,2) -> 0 | Q7: =ROUND(+(O7-P7)*60%,2) -> 0 | R7: =ROUND(+(O7-P7)*40%,2) -> 0 | S7: =IFERROR(ROUND(+Q7/(I7/92%),3),0) -> 0 | W7: 45870 | X7: 10280
B8: =+B7 -> BAN1842 | F8: =IF(+DATE(YEAR(F7),MONTH(F7)+1,1)>$G$1+1,0,+DATE(YEAR(F7),MONTH(F7)+1,1)) -> 183 | G8: =ROUND(IF(F8=0,0,(G7+S7)),3) -> 0 | H8: =ROUND(+G8*$H$1,3) -> 0 | I8: =IFERROR(+VLOOKUP(F8,$W$3:$X$15,2,0),0) -> 0 | J8: 22 | K8: =ROUND(+H8*97%,3) -> 0 | L8: =(K8-H8*92%)*I8 -> 0 | M8: =ROUND(I8*92%*H8,2) -> 0 | N8: =ROUND(+M8*0.11,2) -> 0 | O8: =+N8-L8 -> 0 | P8: =ROUND(+O8*15%,2) -> 0 | Q8: =ROUND(+(O8-P8)*60%,2) -> 0 | R8: =ROUND(+(O8-P8)*40%,2) -> 0 | S8: =IFERROR(ROUND(+Q8/(I8/92%),3),0) -> 0 | W8: 45901 | X8: 10929
B9: =+B8 -> BAN1842 | F9: =IF(+DATE(YEAR(F8),MONTH(F8)+1,1)>$G$1+1,0,+DATE(YEAR(F8),MONTH(F8)+1,1)) -> 214 | G9: =ROUND(IF(F9=0,0,(G8+S8)),3) -> 0 | H9: =ROUND(+G9*$H$1,3) -> 0 | I9: =IFERROR(+VLOOKUP(F9,$W$3:$X$15,2,0),0) -> 0 | J9: 22 | K9: =ROUND(+H9*97%,3) -> 0 | L9: =(K9-H9*92%)*I9 -> 0 | M9: =ROUND(I9*92%*H9,2) -> 0 | N9: =ROUND(+M9*0.11,2) -> 0 | O9: =+N9-L9 -> 0 | P9: =ROUND(+O9*15%,2) -> 0 | Q9: =ROUND(+(O9-P9)*60%,2) -> 0 | R9: =ROUND(+(O9-P9)*40%,2) -> 0 | S9: =IFERROR(ROUND(+Q9/(I9/92%),3),0) -> 0 | W9: 45931 | X9: 12115
B10: =+B9 -> BAN1842 | F10: =IF(+DATE(YEAR(F9),MONTH(F9)+1,1)>$G$1+1,0,+DATE(YEAR(F9),MONTH(F9)+1,1)) -> 245 | G10: =ROUND(IF(F10=0,0,(G9+S9)),3) -> 0 | H10: =ROUND(+G10*$H$1,3) -> 0 | I10: =IFERROR(+VLOOKUP(F10,$W$3:$X$15,2,0),0) -> 0 | J10: 22 | K10: =ROUND(+H10*97%,3) -> 0 | L10: =(K10-H10*92%)*I10 -> 0 | M10: =ROUND(I10*92%*H10,2) -> 0 | N10: =ROUND(+M10*0.11,2) -> 0 | O10: =+N10-L10 -> 0 | P10: =ROUND(+O10*15%,2) -> 0 | Q10: =ROUND(+(O10-P10)*60%,2) -> 0 | R10: =ROUND(+(O10-P10)*40%,2) -> 0 | S10: =IFERROR(ROUND(+Q10/(I10/92%),3),0) -> 0 | W10: 45962 | X10: 12490
B11: =+B10 -> BAN1842 | F11: =IF(+DATE(YEAR(F10),MONTH(F10)+1,1)>$G$1+1,0,+DATE(YEAR(F10),MONTH(F10)+1,1)) -> 275 | G11: =ROUND(IF(F11=0,0,(G10+S10)),3) -> 0 | H11: =ROUND(+G11*$H$1,3) -> 0 | I11: =IFERROR(+VLOOKUP(F11,$W$3:$X$15,2,0),0) -> 0 | J11: 22 | K11: =ROUND(+H11*97%,3) -> 0 | L11: =(K11-H11*92%)*I11 -> 0 | M11: =ROUND(I11*92%*H11,2) -> 0 | N11: =ROUND(+M11*0.11,2) -> 0 | O11: =+N11-L11 -> 0 | P11: =ROUND(+O11*15%,2) -> 0 | Q11: =ROUND(+(O11-P11)*60%,2) -> 0 | R11: =ROUND(+(O11-P11)*40%,2) -> 0 | S11: =IFERROR(ROUND(+Q11/(I11/92%),3),0) -> 0 | W11: 45992 | X11: 13220
B12: =+B11 -> BAN1842 | F12: =IF(+DATE(YEAR(F11),MONTH(F11)+1,1)>$G$1+1,0,+DATE(YEAR(F11),MONTH(F11)+1,1)) -> 306 | G12: =ROUND(IF(F12=0,0,(G11+S11)),3) -> 0 | H12: =ROUND(+G12*$H$1,3) -> 0 | I12: =IFERROR(+VLOOKUP(F12,$W$3:$X$15,2,0),0) -> 0 | J12: 22 | K12: =ROUND(+H12*97%,3) -> 0 | L12: =(K12-H12*92%)*I12 -> 0 | M12: =ROUND(I12*92%*H12,2) -> 0 | N12: =ROUND(+M12*0.11,2) -> 0 | O12: =+N12-L12 -> 0 | P12: =ROUND(+O12*15%,2) -> 0 | Q12: =ROUND(+(O12-P12)*60%,2) -> 0 | R12: =ROUND(+(O12-P12)*40%,2) -> 0 | S12: =IFERROR(ROUND(+Q12/(I12/92%),3),0) -> 0 | W12: 46023 | X12: 13790
B13: =+B12 -> BAN1842 | F13: =IF(+DATE(YEAR(F12),MONTH(F12)+1,1)>$G$1+1,0,+DATE(YEAR(F12),MONTH(F12)+1,1)) -> 336 | G13: =ROUND(IF(F13=0,0,(G12+S12)),3) -> 0 | H13: =ROUND(+G13*$H$1,3) -> 0 | I13: =IFERROR(+VLOOKUP(F13,$W$3:$X$15,2,0),0) -> 0 | J13: 22 | K13: =ROUND(+H13*97%,3) -> 0 | L13: =(K13-H13*92%)*I13 -> 0 | M13: =ROUND(I13*92%*H13,2) -> 0 | N13: =ROUND(+M13*0.11,2) -> 0 | O13: =+N13-L13 -> 0 | P13: =ROUND(+O13*15%,2) -> 0 | Q13: =ROUND(+(O13-P13)*60%,2) -> 0 | R13: =ROUND(+(O13-P13)*40%,2) -> 0 | S13: =IFERROR(ROUND(+Q13/(I13/92%),3),0) -> 0 | W13: 46054 | X13: 15760
B14: =+B13 -> BAN1842 | F14: =IF(+DATE(YEAR(F13),MONTH(F13)+1,1)>$G$1+1,0,+DATE(YEAR(F13),MONTH(F13)+1,1)) -> 367 | G14: =ROUND(IF(F14=0,0,(G13+S13)),3) -> 0 | H14: =ROUND(+G14*$H$1,3) -> 0 | I14: =IFERROR(+VLOOKUP(F14,$W$3:$X$15,2,0),0) -> 0 | J14: 22 | K14: =ROUND(+H14*97%,3) -> 0 | L14: =(K14-H14*92%)*I14 -> 0 | M14: =ROUND(I14*92%*H14,2) -> 0 | N14: =ROUND(+M14*0.11,2) -> 0 | O14: =+N14-L14 -> 0 | P14: =ROUND(+O14*15%,2) -> 0 | Q14: =ROUND(+(O14-P14)*60%,2) -> 0 | R14: =ROUND(+(O14-P14)*40%,2) -> 0 | S14: =IFERROR(ROUND(+Q14/(I14/92%),3),0) -> 0 | W14: 46082 | X14: 17200
W15: 46113 | X15: 15450
A16: TAG NO | B16: TAG NO | C16: Actual Sales Date | D16: Purity | E16: MS design Sold | F16: New Stk Introduce on | G16: New SG Design Introduced | H16: Sales PM | I16: Gold Rate 24K | J16: Purity | K16: Labour cost Price | L16: Labour Cost Charged | M16: Labour Sell Price | N16: Labour Profit Charged | O16: Labour Sharable Profit | P16: Operating Cost 15% | Q16: MS Share | R16: SG Share | S16: MS Profit in Gold
A17: =+A3+1 -> 2 | B17: =INDEX('sale resgister'!B:B,A17+1,1) -> BAN1847 | C17: =+VLOOKUP(B17,'sale resgister'!B:J,9,0) -> 45757 | D17: =+VLOOKUP(B17,'sale resgister'!B:J,2,0) -> Batch 1 | E17: =IF(C17=0,0,VLOOKUP(B17,'sale resgister'!B:J,4,0)) -> 46.893 | F17: =DATE(YEAR(C17),MONTH(C17)+1,1) -> 45778 | G17: =E17 -> 46.893 | H17: =ROUND(+G17*$H$1,3) -> 3.283 | I17: =IFERROR(+VLOOKUP(F17,$W$3:$X$15,2,0),0) -> 9953 | J17: 22 | K17: =ROUND(+H17*97%,3) -> 3.185 | L17: =(K17-H17*92%)*I17 -> 1638.6619 | M17: =ROUND(I17*92%*H17,2) -> 30061.64 | N17: =ROUND(+M17*0.11,2) -> 3306.78 | O17: =+N17-L17 -> 1668.1181 | P17: =ROUND(+O17*15%,2) -> 250.22 | Q17: =ROUND(+(O17-P17)*60%,2) -> 850.74 | R17: =ROUND(+(O17-P17)*40%,2) -> 567.16 | S17: =IFERROR(ROUND(+Q17/(I17/92%),3),0) -> 0.079 | U17: 1633.6854 | V17: =+U17-L17 -> -4.9765
B18: =+B17 -> BAN1847 | F18: =IF(+DATE(YEAR(F17),MONTH(F17)+1,1)>$G$1+1,0,+DATE(YEAR(F17),MONTH(F17)+1,1)) -> 45809 | G18: =ROUND(IF(F18=0,0,(G17+S17)),3) -> 46.972 | H18: =ROUND(+G18*$H$1,3) -> 3.288 | I18: =IFERROR(+VLOOKUP(F18,$W$3:$X$15,2,0),0) -> 9966 | J18: 22 | K18: =ROUND(+H18*97%,3) -> 3.189 | L18: =(K18-H18*92%)*I18 -> 1634.8226 | M18: =ROUND(I18*92%*H18,2) -> 30146.75 | N18: =ROUND(+M18*0.11,2) -> 3316.14 | O18: =+N18-L18 -> 1681.3174 | P18: =ROUND(+O18*15%,2) -> 252.2 | Q18: =ROUND(+(O18-P18)*60%,2) -> 857.47 | R18: =ROUND(+(O18-P18)*40%,2) -> 571.65 | S18: =IFERROR(ROUND(+Q18/(I18/92%),3),0) -> 0.079 | U18: 1638.809 | V18: =+U18-L18 -> 3.9864
B19: =+B18 -> BAN1847 | F19: =IF(+DATE(YEAR(F18),MONTH(F18)+1,1)>$G$1+1,0,+DATE(YEAR(F18),MONTH(F18)+1,1)) -> 45839 | G19: =ROUND(IF(F19=0,0,(G18+S18)),3) -> 47.051 | H19: =ROUND(+G19*$H$1,3) -> 3.294 | I19: =IFERROR(+VLOOKUP(F19,$W$3:$X$15,2,0),0) -> 10008 | J19: 22 | K19: =ROUND(+H19*97%,3) -> 3.195 | L19: =(K19-H19*92%)*I19 -> 1646.5162 | M19: =ROUND(I19*92%*H19,2) -> 30329.04 | N19: =ROUND(+M19*0.11,2) -> 3336.19 | O19: =+N19-L19 -> 1689.6738 | P19: =ROUND(+O19*15%,2) -> 253.45 | Q19: =ROUND(+(O19-P19)*60%,2) -> 861.73 | R19: =ROUND(+(O19-P19)*40%,2) -> 574.49 | S19: =IFERROR(ROUND(+Q19/(I19/92%),3),0) -> 0.079 | U19: 1648.5178 | V19: =+U19-L19 -> 2.0016
B20: =+B19 -> BAN1847 | F20: =IF(+DATE(YEAR(F19),MONTH(F19)+1,1)>$G$1+1,0,+DATE(YEAR(F19),MONTH(F19)+1,1)) -> 45870 | G20: =ROUND(IF(F20=0,0,(G19+S19)),3) -> 47.13 | H20: =ROUND(+G20*$H$1,3) -> 3.299 | I20: =IFERROR(+VLOOKUP(F20,$W$3:$X$15,2,0),0) -> 10280 | J20: 22 | K20: =ROUND(+H20*97%,3) -> 3.2 | L20: =(K20-H20*92%)*I20 -> 1695.3776 | M20: =ROUND(I20*92%*H20,2) -> 31200.62 | N20: =ROUND(+M20*0.11,2) -> 3432.07 | O20: =+N20-L20 -> 1736.6924 | P20: =ROUND(+O20*15%,2) -> 260.5 | Q20: =ROUND(+(O20-P20)*60%,2) -> 885.72 | R20: =ROUND(+(O20-P20)*40%,2) -> 590.48 | S20: =IFERROR(ROUND(+Q20/(I20/92%),3),0) -> 0.079 | U20: 1695.3776 | V20: =+U20-L20 -> 0
B21: =+B20 -> BAN1847 | F21: =IF(+DATE(YEAR(F20),MONTH(F20)+1,1)>$G$1+1,0,+DATE(YEAR(F20),MONTH(F20)+1,1)) -> 45901 | G21: =ROUND(IF(F21=0,0,(G20+S20)),3) -> 47.209 | H21: =ROUND(+G21*$H$1,3) -> 3.305 | I21: =IFERROR(+VLOOKUP(F21,$W$3:$X$15,2,0),0) -> 10929 | J21: 22 | K21: =ROUND(+H21*97%,3) -> 3.206 | L21: =(K21-H21*92%)*I21 -> 1807.6566 | M21: =ROUND(I21*92%*H21,2) -> 33230.72 | N21: =ROUND(+M21*0.11,2) -> 3655.38 | O21: =+N21-L21 -> 1847.7234 | P21: =ROUND(+O21*15%,2) -> 277.16 | Q21: =ROUND(+(O21-P21)*60%,2) -> 942.34 | R21: =ROUND(+(O21-P21)*40%,2) -> 628.23 | S21: =IFERROR(ROUND(+Q21/(I21/92%),3),0) -> 0.079 | U21: 1806.5637 | V21: =+U21-L21 -> -1.0929
B22: =+B21 -> BAN1847 | F22: =IF(+DATE(YEAR(F21),MONTH(F21)+1,1)>$G$1+1,0,+DATE(YEAR(F21),MONTH(F21)+1,1)) -> 45931 | G22: =ROUND(IF(F22=0,0,(G21+S21)),3) -> 47.288 | H22: =ROUND(+G22*$H$1,3) -> 3.31 | I22: =IFERROR(+VLOOKUP(F22,$W$3:$X$15,2,0),0) -> 12115 | J22: 22 | K22: =ROUND(+H22*97%,3) -> 3.211 | L22: =(K22-H22*92%)*I22 -> 2008.667 | M22: =ROUND(I22*92%*H22,2) -> 36892.6 | N22: =ROUND(+M22*0.11,2) -> 4058.19 | O22: =+N22-L22 -> 2049.523 | P22: =ROUND(+O22*15%,2) -> 307.43 | Q22: =ROUND(+(O22-P22)*60%,2) -> 1045.26 | R22: =ROUND(+(O22-P22)*40%,2) -> 696.84 | S22: =IFERROR(ROUND(+Q22/(I22/92%),3),0) -> 0.079 | U22: 2005.0325 | V22: =+U22-L22 -> -3.6345
B23: =+B22 -> BAN1847 | F23: =IF(+DATE(YEAR(F22),MONTH(F22)+1,1)>$G$1+1,0,+DATE(YEAR(F22),MONTH(F22)+1,1)) -> 45962 | G23: =ROUND(IF(F23=0,0,(G22+S22)),3) -> 47.367 | H23: =ROUND(+G23*$H$1,3) -> 3.316 | I23: =IFERROR(+VLOOKUP(F23,$W$3:$X$15,2,0),0) -> 12490 | J23: 22 | K23: =ROUND(+H23*97%,3) -> 3.217 | L23: =(K23-H23*92%)*I23 -> 2076.8372 | M23: =ROUND(I23*92%*H23,2) -> 38103.49 | N23: =ROUND(+M23*0.11,2) -> 4191.38 | O23: =+N23-L23 -> 2114.5428 | P23: =ROUND(+O23*15%,2) -> 317.18 | Q23: =ROUND(+(O23-P23)*60%,2) -> 1078.42 | R23: =ROUND(+(O23-P23)*40%,2) -> 718.95 | S23: =IFERROR(ROUND(+Q23/(I23/92%),3),0) -> 0.079 | U23: 2070.5922 | V23: =+U23-L23 -> -6.245
B24: =+B23 -> BAN1847 | F24: =IF(+DATE(YEAR(F23),MONTH(F23)+1,1)>$G$1+1,0,+DATE(YEAR(F23),MONTH(F23)+1,1)) -> 45992 | G24: =ROUND(IF(F24=0,0,(G23+S23)),3) -> 47.446 | H24: =ROUND(+G24*$H$1,3) -> 3.321 | I24: =IFERROR(+VLOOKUP(F24,$W$3:$X$15,2,0),0) -> 13220 | J24: 22 | K24: =ROUND(+H24*97%,3) -> 3.221 | L24: =(K24-H24*92%)*I24 -> 2190.2896 | M24: =ROUND(I24*92%*H24,2) -> 40391.33 | N24: =ROUND(+M24*0.11,2) -> 4443.05 | O24: =+N24-L24 -> 2252.7604 | P24: =ROUND(+O24*15%,2) -> 337.91 | Q24: =ROUND(+(O24-P24)*60%,2) -> 1148.91 | R24: =ROUND(+(O24-P24)*40%,2) -> 765.94 | S24: =IFERROR(ROUND(+Q24/(I24/92%),3),0) -> 0.08 | U24: 2195.5776 | V24: =+U24-L24 -> 5.288
B25: =+B24 -> BAN1847 | F25: =IF(+DATE(YEAR(F24),MONTH(F24)+1,1)>$G$1+1,0,+DATE(YEAR(F24),MONTH(F24)+1,1)) -> 46023 | G25: =ROUND(IF(F25=0,0,(G24+S24)),3) -> 47.526 | H25: =ROUND(+G25*$H$1,3) -> 3.327 | I25: =IFERROR(+VLOOKUP(F25,$W$3:$X$15,2,0),0) -> 13790 | J25: 22 | K25: =ROUND(+H25*97%,3) -> 3.227 | L25: =(K25-H25*92%)*I25 -> 2291.3464 | M25: =ROUND(I25*92%*H25,2) -> 42208.98 | N25: =ROUND(+M25*0.11,2) -> 4642.99 | O25: =+N25-L25 -> 2351.6436 | P25: =ROUND(+O25*15%,2) -> 352.75 | Q25: =ROUND(+(O25-P25)*60%,2) -> 1199.34 | R25: =ROUND(+(O25-P25)*40%,2) -> 799.56 | S25: =IFERROR(ROUND(+Q25/(I25/92%),3),0) -> 0.08 | U25: 2294.1044 | V25: =+U25-L25 -> 2.758
B26: =+B25 -> BAN1847 | F26: =IF(+DATE(YEAR(F25),MONTH(F25)+1,1)>$G$1+1,0,+DATE(YEAR(F25),MONTH(F25)+1,1)) -> 46054 | G26: =ROUND(IF(F26=0,0,(G25+S25)),3) -> 47.606 | H26: =ROUND(+G26*$H$1,3) -> 3.332 | I26: =IFERROR(+VLOOKUP(F26,$W$3:$X$15,2,0),0) -> 15760 | J26: 22 | K26: =ROUND(+H26*97%,3) -> 3.232 | L26: =(K26-H26*92%)*I26 -> 2624.9856 | M26: =ROUND(I26*92%*H26,2) -> 48311.33 | N26: =ROUND(+M26*0.11,2) -> 5314.25 | O26: =+N26-L26 -> 2689.2644 | P26: =ROUND(+O26*15%,2) -> 403.39 | Q26: =ROUND(+(O26-P26)*60%,2) -> 1371.52 | R26: =ROUND(+(O26-P26)*40%,2) -> 914.35 | S26: =IFERROR(ROUND(+Q26/(I26/92%),3),0) -> 0.08 | U26: 2626.2464 | V26: =+U26-L26 -> 1.2608
B27: =+B26 -> BAN1847 | F27: =IF(+DATE(YEAR(F26),MONTH(F26)+1,1)>$G$1+1,0,+DATE(YEAR(F26),MONTH(F26)+1,1)) -> 46082 | G27: =ROUND(IF(F27=0,0,(G26+S26)),3) -> 47.686 | H27: =ROUND(+G27*$H$1,3) -> 3.338 | I27: =IFERROR(+VLOOKUP(F27,$W$3:$X$15,2,0),0) -> 17200 | J27: 22 | K27: =ROUND(+H27*97%,3) -> 3.238 | L27: =(K27-H27*92%)*I27 -> 2873.088 | M27: =ROUND(I27*92%*H27,2) -> 52820.51 | N27: =ROUND(+M27*0.11,2) -> 5810.26 | O27: =+N27-L27 -> 2937.172 | P27: =ROUND(+O27*15%,2) -> 440.58 | Q27: =ROUND(+(O27-P27)*60%,2) -> 1497.96 | R27: =ROUND(+(O27-P27)*40%,2) -> 998.64 | S27: =IFERROR(ROUND(+Q27/(I27/92%),3),0) -> 0.08 | U27: 2871.368 | V27: =+U27-L27 -> -1.72
B28: =+B27 -> BAN1847 | F28: =IF(+DATE(YEAR(F27),MONTH(F27)+1,1)>$G$1+1,0,+DATE(YEAR(F27),MONTH(F27)+1,1)) -> 46113 | G28: =ROUND(IF(F28=0,0,(G27+S27)),3) -> 47.766 | H28: =ROUND(+G28*$H$1,3) -> 3.344 | I28: =IFERROR(+VLOOKUP(F28,$W$3:$X$15,2,0),0) -> 15450 | J28: 22 | K28: =ROUND(+H28*97%,3) -> 3.244 | L28: =(K28-H28*92%)*I28 -> 2588.184 | M28: =ROUND(I28*92%*H28,2) -> 47531.62 | N28: =ROUND(+M28*0.11,2) -> 5228.48 | O28: =+N28-L28 -> 2640.296 | P28: =ROUND(+O28*15%,2) -> 396.04 | Q28: =ROUND(+(O28-P28)*60%,2) -> 1346.55 | R28: =ROUND(+(O28-P28)*40%,2) -> 897.7 | S28: =IFERROR(ROUND(+Q28/(I28/92%),3),0) -> 0.08 | U28: 2583.549 | V28: =+U28-L28 -> -4.635
V29: =SUM(V17:V28) -> -7.0091
A30: TAG NO | B30: TAG NO | C30: Actual Sales Date | D30: Purity | E30: MS design Sold | F30: New Stk Introduce on | G30: New SG Design Introduced | H30: Sales PM | I30: Gold Rate 24K | J30: Purity | K30: Labour cost Price | L30: Labour Cost Charged | M30: Labour Sell Price | N30: Labour Profit Charged | O30: Labour Sharable Profit | P30: Operating Cost 15% | Q30: MS Share | R30: SG Share | S30: MS Profit in Gold
A31: =+A17+1 -> 3 | B31: =INDEX('sale resgister'!B:B,A31+1,1) -> BAN1846 | C31: =+VLOOKUP(B31,'sale resgister'!B:J,9,0) -> 0 | D31: =+VLOOKUP(B31,'sale resgister'!B:J,2,0) -> Batch 1 | E31: =IF(C31=0,0,VLOOKUP(B31,'sale resgister'!B:J,4,0)) -> 0 | F31: =DATE(YEAR(C31),MONTH(C31)+1,1) -> 32 | G31: =E31 -> 0 | H31: =ROUND(+G31*$H$1,3) -> 0 | I31: =IFERROR(+VLOOKUP(F31,$W$3:$X$15,2,0),0) -> 0 | J31: 22 | K31: =ROUND(+H31*97%,3) -> 0 | L31: =(K31-H31*92%)*I31 -> 0 | M31: =ROUND(I31*92%*H31,2) -> 0 | N31: =ROUND(+M31*0.11,2) -> 0 | O31: =+N31-L31 -> 0 | P31: =ROUND(+O31*15%,2) -> 0 | Q31: =ROUND(+(O31-P31)*60%,2) -> 0 | R31: =ROUND(+(O31-P31)*40%,2) -> 0 | S31: =IFERROR(ROUND(+Q31/(I31/92%),3),0) -> 0
B32: =+B31 -> BAN1846 | F32: =IF(+DATE(YEAR(F31),MONTH(F31)+1,1)>$G$1+1,0,+DATE(YEAR(F31),MONTH(F31)+1,1)) -> 61 | G32: =ROUND(IF(F32=0,0,(G31+S31)),3) -> 0 | H32: =ROUND(+G32*$H$1,3) -> 0 | I32: =IFERROR(+VLOOKUP(F32,$W$3:$X$15,2,0),0) -> 0 | J32: 22 | K32: =ROUND(+H32*97%,3) -> 0 | L32: =(K32-H32*92%)*I32 -> 0 | M32: =ROUND(I32*92%*H32,2) -> 0 | N32: =ROUND(+M32*0.11,2) -> 0 | O32: =+N32-L32 -> 0 | P32: =ROUND(+O32*15%,2) -> 0 | Q32: =ROUND(+(O32-P32)*60%,2) -> 0 | R32: =ROUND(+(O32-P32)*40%,2) -> 0 | S32: =IFERROR(ROUND(+Q32/(I32/92%),3),0) -> 0
B33: =+B32 -> BAN1846 | F33: =IF(+DATE(YEAR(F32),MONTH(F32)+1,1)>$G$1+1,0,+DATE(YEAR(F32),MONTH(F32)+1,1)) -> 92 | G33: =ROUND(IF(F33=0,0,(G32+S32)),3) -> 0 | H33: =ROUND(+G33*$H$1,3) -> 0 | I33: =IFERROR(+VLOOKUP(F33,$W$3:$X$15,2,0),0) -> 0 | J33: 22 | K33: =ROUND(+H33*97%,3) -> 0 | L33: =(K33-H33*92%)*I33 -> 0 | M33: =ROUND(I33*92%*H33,2) -> 0 | N33: =ROUND(+M33*0.11,2) -> 0 | O33: =+N33-L33 -> 0 | P33: =ROUND(+O33*15%,2) -> 0 | Q33: =ROUND(+(O33-P33)*60%,2) -> 0 | R33: =ROUND(+(O33-P33)*40%,2) -> 0 | S33: =IFERROR(ROUND(+Q33/(I33/92%),3),0) -> 0
B34: =+B33 -> BAN1846 | F34: =IF(+DATE(YEAR(F33),MONTH(F33)+1,1)>$G$1+1,0,+DATE(YEAR(F33),MONTH(F33)+1,1)) -> 122 | G34: =ROUND(IF(F34=0,0,(G33+S33)),3) -> 0 | H34: =ROUND(+G34*$H$1,3) -> 0 | I34: =IFERROR(+VLOOKUP(F34,$W$3:$X$15,2,0),0) -> 0 | J34: 22 | K34: =ROUND(+H34*97%,3) -> 0 | L34: =(K34-H34*92%)*I34 -> 0 | M34: =ROUND(I34*92%*H34,2) -> 0 | N34: =ROUND(+M34*0.11,2) -> 0 | O34: =+N34-L34 -> 0 | P34: =ROUND(+O34*15%,2) -> 0 | Q34: =ROUND(+(O34-P34)*60%,2) -> 0 | R34: =ROUND(+(O34-P34)*40%,2) -> 0 | S34: =IFERROR(ROUND(+Q34/(I34/92%),3),0) -> 0
B35: =+B34 -> BAN1846 | F35: =IF(+DATE(YEAR(F34),MONTH(F34)+1,1)>$G$1+1,0,+DATE(YEAR(F34),MONTH(F34)+1,1)) -> 153 | G35: =ROUND(IF(F35=0,0,(G34+S34)),3) -> 0 | H35: =ROUND(+G35*$H$1,3) -> 0 | I35: =IFERROR(+VLOOKUP(F35,$W$3:$X$15,2,0),0) -> 0 | J35: 22 | K35: =ROUND(+H35*97%,3) -> 0 | L35: =(K35-H35*92%)*I35 -> 0 | M35: =ROUND(I35*92%*H35,2) -> 0 | N35: =ROUND(+M35*0.11,2) -> 0 | O35: =+N35-L35 -> 0 | P35: =ROUND(+O35*15%,2) -> 0 | Q35: =ROUND(+(O35-P35)*60%,2) -> 0 | R35: =ROUND(+(O35-P35)*40%,2) -> 0 | S35: =IFERROR(ROUND(+Q35/(I35/92%),3),0) -> 0
B36: =+B35 -> BAN1846 | F36: =IF(+DATE(YEAR(F35),MONTH(F35)+1,1)>$G$1+1,0,+DATE(YEAR(F35),MONTH(F35)+1,1)) -> 183 | G36: =ROUND(IF(F36=0,0,(G35+S35)),3) -> 0 | H36: =ROUND(+G36*$H$1,3) -> 0 | I36: =IFERROR(+VLOOKUP(F36,$W$3:$X$15,2,0),0) -> 0 | J36: 22 | K36: =ROUND(+H36*97%,3) -> 0 | L36: =(K36-H36*92%)*I36 -> 0 | M36: =ROUND(I36*92%*H36,2) -> 0 | N36: =ROUND(+M36*0.11,2) -> 0 | O36: =+N36-L36 -> 0 | P36: =ROUND(+O36*15%,2) -> 0 | Q36: =ROUND(+(O36-P36)*60%,2) -> 0 | R36: =ROUND(+(O36-P36)*40%,2) -> 0 | S36: =IFERROR(ROUND(+Q36/(I36/92%),3),0) -> 0
B37: =+B36 -> BAN1846 | F37: =IF(+DATE(YEAR(F36),MONTH(F36)+1,1)>$G$1+1,0,+DATE(YEAR(F36),MONTH(F36)+1,1)) -> 214 | G37: =ROUND(IF(F37=0,0,(G36+S36)),3) -> 0 | H37: =ROUND(+G37*$H$1,3) -> 0 | I37: =IFERROR(+VLOOKUP(F37,$W$3:$X$15,2,0),0) -> 0 | J37: 22 | K37: =ROUND(+H37*97%,3) -> 0 | L37: =(K37-H37*92%)*I37 -> 0 | M37: =ROUND(I37*92%*H37,2) -> 0 | N37: =ROUND(+M37*0.11,2) -> 0 | O37: =+N37-L37 -> 0 | P37: =ROUND(+O37*15%,2) -> 0 | Q37: =ROUND(+(O37-P37)*60%,2) -> 0 | R37: =ROUND(+(O37-P37)*40%,2) -> 0 | S37: =IFERROR(ROUND(+Q37/(I37/92%),3),0) -> 0
B38: =+B37 -> BAN1846 | F38: =IF(+DATE(YEAR(F37),MONTH(F37)+1,1)>$G$1+1,0,+DATE(YEAR(F37),MONTH(F37)+1,1)) -> 245 | G38: =ROUND(IF(F38=0,0,(G37+S37)),3) -> 0 | H38: =ROUND(+G38*$H$1,3) -> 0 | I38: =IFERROR(+VLOOKUP(F38,$W$3:$X$15,2,0),0) -> 0 | J38: 22 | K38: =ROUND(+H38*97%,3) -> 0 | L38: =(K38-H38*92%)*I38 -> 0 | M38: =ROUND(I38*92%*H38,2) -> 0 | N38: =ROUND(+M38*0.11,2) -> 0 | O38: =+N38-L38 -> 0 | P38: =ROUND(+O38*15%,2) -> 0 | Q38: =ROUND(+(O38-P38)*60%,2) -> 0 | R38: =ROUND(+(O38-P38)*40%,2) -> 0 | S38: =IFERROR(ROUND(+Q38/(I38/92%),3),0) -> 0
B39: =+B38 -> BAN1846 | F39: =IF(+DATE(YEAR(F38),MONTH(F38)+1,1)>$G$1+1,0,+DATE(YEAR(F38),MONTH(F38)+1,1)) -> 275 | G39: =ROUND(IF(F39=0,0,(G38+S38)),3) -> 0 | H39: =ROUND(+G39*$H$1,3) -> 0 | I39: =IFERROR(+VLOOKUP(F39,$W$3:$X$15,2,0),0) -> 0 | J39: 22 | K39: =ROUND(+H39*97%,3) -> 0 | L39: =(K39-H39*92%)*I39 -> 0 | M39: =ROUND(I39*92%*H39,2) -> 0 | N39: =ROUND(+M39*0.11,2) -> 0 | O39: =+N39-L39 -> 0 | P39: =ROUND(+O39*15%,2) -> 0 | Q39: =ROUND(+(O39-P39)*60%,2) -> 0 | R39: =ROUND(+(O39-P39)*40%,2) -> 0 | S39: =IFERROR(ROUND(+Q39/(I39/92%),3),0) -> 0
B40: =+B39 -> BAN1846 | F40: =IF(+DATE(YEAR(F39),MONTH(F39)+1,1)>$G$1+1,0,+DATE(YEAR(F39),MONTH(F39)+1,1)) -> 306 | G40: =ROUND(IF(F40=0,0,(G39+S39)),3) -> 0 | H40: =ROUND(+G40*$H$1,3) -> 0 | I40: =IFERROR(+VLOOKUP(F40,$W$3:$X$15,2,0),0) -> 0 | J40: 22 | K40: =ROUND(+H40*97%,3) -> 0 | L40: =(K40-H40*92%)*I40 -> 0 | M40: =ROUND(I40*92%*H40,2) -> 0 | N40: =ROUND(+M40*0.11,2) -> 0 | O40: =+N40-L40 -> 0 | P40: =ROUND(+O40*15%,2) -> 0 | Q40: =ROUND(+(O40-P40)*60%,2) -> 0 | R40: =ROUND(+(O40-P40)*40%,2) -> 0 | S40: =IFERROR(ROUND(+Q40/(I40/92%),3),0) -> 0
...

Sheet P&L REPORT 3
G1: 46112 | H1: 0.07
A2: Sr. No | B2: TAG NO | C2: Actual Sales Date | D2: Purity | E2: MS design Sold | F2: New Stk Introduce on | G2: New SG Design Introduced | H2: Sales PM | I2: Gold Rate 24K | J2: Purity | K2: Labour cost Price | L2: Labour Cost Charged | M2: Labour Sell Price | N2: Labour Profit Charged | O2: Labour Sharable Profit | P2: Operating Cost 15% | Q2: MS Share | R2: SG Share | S2: MS Profit in Gold
A3: 1 | C3: 45757 | E3: =311.303 -> 311.303 | F3: =DATE(YEAR(C3),MONTH(C3)+1,1) -> 45778 | G3: =E3 -> 311.303 | H3: =ROUND(+G3*$H$1,3) -> 21.791 | I3: 9642 | J3: 22 | K3: =ROUND(+H3*97%,2) -> 21.14 | L3: =(K3-H3*92%)*I3 -> 10531.764 | M3: =ROUND(I3*92%*H3,2) -> 193300.12 | N3: =ROUND(+M3*0.11,2) -> 21263.01 | O3: =+N3-L3 -> 10731.246 | P3: =ROUND(+O3*15%,2) -> 1609.69 | Q3: =ROUND(+(O3-P3)*60%,2) -> 5472.93 | R3: =ROUND(+(O3-P3)*40%,2) -> 3648.62 | S3: =ROUND(+Q3/(I3/92%),3) -> 0.522
F4: =IF(+DATE(YEAR(F3),MONTH(F3)+1,1)>$G$1+1,0,+DATE(YEAR(F3),MONTH(F3)+1,1)) -> 45809 | G4: =ROUND(IF(F4=0,0,(G3+S3)),3) -> 311.825 | H4: =ROUND(+G4*$H$1,3) -> 21.828 | I4: 9960 | J4: 22 | K4: =ROUND(+H4*97%,2) -> 21.17 | L4: =(K4-H4*92%)*I4 -> 10838.87 | M4: =ROUND(I4*92%*H4,2) -> 200014.33 | N4: =ROUND(+M4*0.11,2) -> 22001.58 | O4: =+N4-L4 -> 11162.71 | P4: =ROUND(+O4*15%,2) -> 1674.41 | Q4: =ROUND(+(O4-P4)*60%,2) -> 5692.98 | R4: =ROUND(+(O4-P4)*40%,2) -> 3795.32 | S4: =ROUND(+Q4/(I4/92%),3) -> 0.526
F5: =IF(+DATE(YEAR(F4),MONTH(F4)+1,1)>$G$1+1,0,+DATE(YEAR(F4),MONTH(F4)+1,1)) -> 45839 | G5: =ROUND(IF(F5=0,0,(G4+S4)),3) -> 312.351 | H5: =ROUND(+G5*$H$1,3) -> 21.865 | I5: 10008 | J5: 22 | K5: =ROUND(+H5*97%,2) -> 21.21 | L5: =(K5-H5*92%)*I5 -> 10950.754 | M5: =ROUND(I5*92%*H5,2) -> 201318.93 | N5: =ROUND(+M5*0.11,2) -> 22145.08 | O5: =+N5-L5 -> 11194.326 | P5: =ROUND(+O5*15%,2) -> 1679.15 | Q5: =ROUND(+(O5-P5)*60%,2) -> 5709.11 | R5: =ROUND(+(O5-P5)*40%,2) -> 3806.07 | S5: =ROUND(+Q5/(I5/92%),3) -> 0.525
F6: =IF(+DATE(YEAR(F5),MONTH(F5)+1,1)>$G$1+1,0,+DATE(YEAR(F5),MONTH(F5)+1,1)) -> 45870 | G6: =ROUND(IF(F6=0,0,(G5+S5)),3) -> 312.876 | H6: =ROUND(+G6*$H$1,3) -> 21.901 | I6: 10280 | J6: 22 | K6: =ROUND(+H6*97%,2) -> 21.24 | L6: =(K6-H6*92%)*I6 -> 11216.302 | M6: =ROUND(I6*92%*H6,2) -> 207130.9 | N6: =ROUND(+M6*0.11,2) -> 22784.4 | O6: =+N6-L6 -> 11568.098 | P6: =ROUND(+O6*15%,2) -> 1735.21 | Q6: =ROUND(+(O6-P6)*60%,2) -> 5899.73 | R6: =ROUND(+(O6-P6)*40%,2) -> 3933.16 | S6: =ROUND(+Q6/(I6/92%),3) -> 0.528
F7: =IF(+DATE(YEAR(F6),MONTH(F6)+1,1)>$G$1+1,0,+DATE(YEAR(F6),MONTH(F6)+1,1)) -> 45901 | G7: =ROUND(IF(F7=0,0,(G6+S6)),3) -> 313.404 | H7: =ROUND(+G7*$H$1,3) -> 21.938 | I7: 10929 | J7: 22 | K7: =ROUND(+H7*97%,2) -> 21.28 | L7: =(K7-H7*92%)*I7 -> 11989.55 | M7: =ROUND(I7*92%*H7,2) -> 220579.57 | N7: =ROUND(+M7*0.11,2) -> 24263.75 | O7: =+N7-L7 -> 12274.2 | P7: =ROUND(+O7*15%,2) -> 1841.13 | Q7: =ROUND(+(O7-P7)*60%,2) -> 6259.84 | R7: =ROUND(+(O7-P7)*40%,2) -> 4173.23 | S7: =ROUND(+Q7/(I7/92%),3) -> 0.527
F8: =IF(+DATE(YEAR(F7),MONTH(F7)+1,1)>$G$1+1,0,+DATE(YEAR(F7),MONTH(F7)+1,1)) -> 45931 | G8: =ROUND(IF(F8=0,0,(G7+S7)),3) -> 313.931 | H8: =ROUND(+G8*$H$1,3) -> 21.975 | I8: 12115 | J8: 22 | K8: =ROUND(+H8*97%,2) -> 21.32 | L8: =(K8-H8*92%)*I8 -> 13362.845 | M8: =ROUND(I8*92%*H8,2) -> 244928.96 | N8: =ROUND(+M8*0.11,2) -> 26942.19 | O8: =+N8-L8 -> 13579.345 | P8: =ROUND(+O8*15%,2) -> 2036.9 | Q8: =ROUND(+(O8-P8)*60%,2) -> 6925.47 | R8: =ROUND(+(O8-P8)*40%,2) -> 4616.98 | S8: =ROUND(+Q8/(I8/92%),3) -> 0.526
F9: =IF(+DATE(YEAR(F8),MONTH(F8)+1,1)>$G$1+1,0,+DATE(YEAR(F8),MONTH(F8)+1,1)) -> 45962 | G9: =ROUND(IF(F9=0,0,(G8+S8)),3) -> 314.457 | H9: =ROUND(+G9*$H$1,3) -> 22.012 | I9: 12490 | J9: 22 | K9: =ROUND(+H9*97%,2) -> 21.35 | L9: =(K9-H9*92%)*I9 -> 13726.01 | M9: =ROUND(I9*92%*H9,2) -> 252935.49 | N9: =ROUND(+M9*0.11,2) -> 27822.9 | O9: =+N9-L9 -> 14096.89 | P9: =ROUND(+O9*15%,2) -> 2114.53 | Q9: =ROUND(+(O9-P9)*60%,2) -> 7189.42 | R9: =ROUND(+(O9-P9)*40%,2) -> 4792.94 | S9: =ROUND(+Q9/(I9/92%),3) -> 0.53
F10: =IF(+DATE(YEAR(F9),MONTH(F9)+1,1)>$G$1+1,0,+DATE(YEAR(F9),MONTH(F9)+1,1)) -> 45992 | G10: =ROUND(IF(F10=0,0,(G9+S9)),3) -> 314.987 | H10: =ROUND(+G10*$H$1,3) -> 22.049 | I10: 13320 | J10: 22 | K10: =ROUND(+H10*97%,2) -> 21.39 | L10: =(K10-H10*92%)*I10 -> 14717.534 | M10: =ROUND(I10*92%*H10,2) -> 270197.27 | N10: =ROUND(+M10*0.11,2) -> 29721.7 | O10: =+N10-L10 -> 15004.166 | P10: =ROUND(+O10*15%,2) -> 2250.62 | Q10: =ROUND(+(O10-P10)*60%,2) -> 7652.13 | R10: =ROUND(+(O10-P10)*40%,2) -> 5101.42 | S10: =ROUND(+Q10/(I10/92%),3) -> 0.529
F11: =IF(+DATE(YEAR(F10),MONTH(F10)+1,1)>$G$1+1,0,+DATE(YEAR(F10),MONTH(F10)+1,1)) -> 46023 | G11: =ROUND(IF(F11=0,0,(G10+S10)),3) -> 315.516 | H11: =ROUND(+G11*$H$1,3) -> 22.086 | I11: 13790 | J11: 22 | K11: =ROUND(+H11*97%,2) -> 21.42 | L11: =(K11-H11*92%)*I11 -> 15181.135 | M11: =ROUND(I11*92%*H11,2) -> 280200.66 | N11: =ROUND(+M11*0.11,2) -> 30822.07 | O11: =+N11-L11 -> 15640.935 | P11: =ROUND(+O11*15%,2) -> 2346.14 | Q11: =ROUND(+(O11-P11)*60%,2) -> 7976.88 | R11: =ROUND(+(O11-P11)*40%,2) -> 5317.92 | S11: =ROUND(+Q11/(I11/92%),3) -> 0.532
F12: =IF(+DATE(YEAR(F11),MONTH(F11)+1,1)>$G$1+1,0,+DATE(YEAR(F11),MONTH(F11)+1,1)) -> 46054 | G12: =ROUND(IF(F12=0,0,(G11+S11)),3) -> 316.048 | H12: =ROUND(+G12*$H$1,3) -> 22.123 | I12: 15760 | J12: 22 | K12: =ROUND(+H12*97%,2) -> 21.46 | L12: =(K12-H12*92%)*I12 -> 17443.798 | M12: =ROUND(I12*92%*H12,2) -> 320765.8 | N12: =ROUND(+M12*0.11,2) -> 35284.24 | O12: =+N12-L12 -> 17840.442 | P12: =ROUND(+O12*15%,2) -> 2676.07 | Q12: =ROUND(+(O12-P12)*60%,2) -> 9098.62 | R12: =ROUND(+(O12-P12)*40%,2) -> 6065.75 | S12: =ROUND(+Q12/(I12/92%),3) -> 0.531
F13: =IF(+DATE(YEAR(F12),MONTH(F12)+1,1)>$G$1+1,0,+DATE(YEAR(F12),MONTH(F12)+1,1)) -> 46082 | G13: =ROUND(IF(F13=0,0,(G12+S12)),3) -> 316.579 | H13: =ROUND(+G13*$H$1,3) -> 22.161 | I13: 17200 | J13: 22 | K13: =ROUND(+H13*97%,2) -> 21.5 | L13: =(K13-H13*92%)*I13 -> 19124.336 | M13: =ROUND(I13*92%*H13,2) -> 350675.66 | N13: =ROUND(+M13*0.11,2) -> 38574.32 | O13: =+N13-L13 -> 19449.984 | P13: =ROUND(+O13*15%,2) -> 2917.5 | Q13: =ROUND(+(O13-P13)*60%,2) -> 9919.49 | R13: =ROUND(+(O13-P13)*40%,2) -> 6612.99 | S13: =ROUND(+Q13/(I13/92%),3) -> 0.531
F14: =IF(+DATE(YEAR(F13),MONTH(F13)+1,1)>$G$1+1,0,+DATE(YEAR(F13),MONTH(F13)+1,1)) -> 46113 | G14: =ROUND(IF(F14=0,0,(G13+S13)),3) -> 317.11 | H14: =ROUND(+G14*$H$1,3) -> 22.198 | I14: 15370 | J14: 22 | K14: =ROUND(+H14*97%,2) -> 21.53 | L14: =(K14-H14*92%)*I14 -> 17027.501 | M14: =ROUND(I14*92%*H14,2) -> 313888.6 | N14: =ROUND(+M14*0.11,2) -> 34527.75 | O14: =+N14-L14 -> 17500.249 | P14: =ROUND(+O14*15%,2) -> 2625.04 | Q14: =ROUND(+(O14-P14)*60%,2) -> 8925.13 | R14: =ROUND(+(O14-P14)*40%,2) -> 5950.08 | S14: =ROUND(+Q14/(I14/92%),3) -> 0.534
P15: =SUM(P3:P14) -> 25506.39 | Q15: =SUM(Q3:Q14) -> 86721.73 | R15: =SUM(R3:R14) -> 57814.48
